Workbook

Sheet RESOLUCIONES EPG
A1: ESCUELA DE POSGRADO UNVERSIDAD ANDINA DEL CUSCO
A4: RESOLUCIONES EMITIDAS 2015-2025
A7: N° SOLICITUD | B7: N° SOLICITUD2 | C7: RESOL. N° | D7: FECHA | E7: NOMBRES Y APELLIDOS | F7: CODIGO | G7: TIPO DE RESOLUCION | H7: Obaservaciones | I7: RESOLUCION 2 | J7: RESOLUCION 3 | K7: RESOLUCION 4 | L7: RESOLUCION 5 | M7: RESOLUCION 6 | N7: HOY | O7: Dias de la resolucion
A8: ='RESOLUCIONES 2015'!A5868:H5868 | B8: 44613 | C8: 7 | D8: 42044 | E8: TANIA KARINA ECHEGARAY CASTILLO | G8: NOMBRAMIENTO DE ASESOR | N8: =TODAY() -> 46206 | O8: ='RESOLUCIONES EPG'!$N8-'RESOLUCIONES EPG'!$D8 -> 4162
A9: ='RESOLUCIONES 2015'!A5879:H5879 | B9: 1603 | C9: 18 | D9: 42044 | E9: SHAILI JULIE CAVERO PACHECO | G9: NOMBRAMIENTO DE ASESOR | N9: =TODAY() -> 46206 | O9: ='RESOLUCIONES EPG'!$N9-'RESOLUCIONES EPG'!$D9 -> 4162
A10: ='RESOLUCIONES 2015'!A5864:H5864 | B10: 34309 | C10: 3 | D10: 42044 | E10: PASTORA AYDEEE MOGROVEJO | G10: APTO PARA SUSTENCION DE TESIS | N10: =TODAY() -> 46206 | O10: ='RESOLUCIONES EPG'!$N10-'RESOLUCIONES EPG'!$D10 -> 4162
A11: ='RESOLUCIONES 2015'!A5870:H5870 | B11: 27237 | C11: 9 | D11: 42044 | E11: PAOLA ESTRADA SANCHEZ | G11: APROBAR Y AUTORIZAR INSCRIPCION | N11: =TODAY() -> 46206 | O11: ='RESOLUCIONES EPG'!$N11-'RESOLUCIONES EPG'!$D11 -> 4162
A12: ='RESOLUCIONES 2015'!A5877:H5877 | B12: 44850 | C12: 16 | D12: 42044 | E12: MARIA LILIANA PEÑA FARFAN | G12: NOMBRAMIENTO DE ASESOR | N12: =TODAY() -> 46206 | O12: ='RESOLUCIONES EPG'!$N12-'RESOLUCIONES EPG'!$D12 -> 4162
A13: ='RESOLUCIONES 2015'!A5862:H5862 | B13: 42296 | C13: 1 | D13: 42044 | E13: MARCO FERNANDO CARPIO SANCHEZ | G13: MOFICAR RESOL. 044-2012/EPG-UAC TITULO DE TRABAJO | N13: =TODAY() -> 46206 | O13: ='RESOLUCIONES EPG'!$N13-'RESOLUCIONES EPG'!$D13 -> 4162
A14: ='RESOLUCIONES 2015'!A5865:H5865 | B14: 44228 | C14: 4 | D14: 42044 | E14: LUZ MARIA CAHUANA FERNANDEZ | G14: DESIGNACION DE DICTAMINANTES | N14: =TODAY() -> 46206 | O14: ='RESOLUCIONES EPG'!$N14-'RESOLUCIONES EPG'!$D14 -> 4162
A15: ='RESOLUCIONES 2015'!A5875:H5875 | B15: 44345 | C15: 14 | D15: 42044 | E15: KELLY OLIVERA OJEDA | G15: DESIGNACION DE DICTAMINANTES | N15: =TODAY() -> 46206 | O15: ='RESOLUCIONES EPG'!$N15-'RESOLUCIONES EPG'!$D15 -> 4162
A16: ='RESOLUCIONES 2015'!A5866:H5866 | B16: 43489 | C16: 5 | D16: 42044 | E16: KARLA FERNANDEZ TOHALINO | G16: DESIGNACION DE DICTAMINANTES | N16: =TODAY() -> 46206 | O16: ='RESOLUCIONES EPG'!$N16-'RESOLUCIONES EPG'!$D16 -> 4162
A17: ='RESOLUCIONES 2015'!A5871:H5871 | B17: 44733 | C17: 10 | D17: 42044 | E17: JOSE LUIS ESQUIVEL TAIPE | G17: NOMBRAMIENTO DE ASESOR | N17: =TODAY() -> 46206 | O17: ='RESOLUCIONES EPG'!$N17-'RESOLUCIONES EPG'!$D17 -> 4162
A18: ='RESOLUCIONES 2015'!A5872:H5872 | B18: 44374 | C18: 11 | D18: 42044 | E18: JOSE LUIS ESQUIVEL TAIPE | G18: DESIGNACION DE DICTAMINANTES | N18: =TODAY() -> 46206 | O18: ='RESOLUCIONES EPG'!$N18-'RESOLUCIONES EPG'!$D18 -> 4162
A19: ='RESOLUCIONES 2015'!A5876:H5876 | B19: 44823 | C19: 15 | D19: 42044 | E19: JAVIER ORLANDO CUNZA | G19: NOMBRAMIENTO DE ASESOR | N19: =TODAY() -> 46206 | O19: ='RESOLUCIONES EPG'!$N19-'RESOLUCIONES EPG'!$D19 -> 4162
A20: ='RESOLUCIONES 2015'!A5878:H5878 | B20: 44739 | C20: 17 | D20: 42044 | E20: JACKELINE CECILIA ORQQUE CHACON | G20: NOMBRAMIENTO DE ASESOR | N20: =TODAY() -> 46206 | O20: ='RESOLUCIONES EPG'!$N20-'RESOLUCIONES EPG'!$D20 -> 4162
A21: ='RESOLUCIONES 2015'!A5873:H5873 | B21: 44794 | C21: 12 | D21: 42044 | E21: GLORIA CHACON ORDOÑEZ | G21: DESIGNACION DE DICTAMINANTES | N21: =TODAY() -> 46206 | O21: ='RESOLUCIONES EPG'!$N21-'RESOLUCIONES EPG'!$D21 -> 4162
A22: ='RESOLUCIONES 2015'!A5869:H5869 | B22: 41942 | C22: 8 | D22: 42044 | E22: GISELA GIOVANA PUELLES FOLLANA | G22: DESIGNACION DE DICTAMINANTES | N22: =TODAY() -> 46206 | O22: ='RESOLUCIONES EPG'!$N22-'RESOLUCIONES EPG'!$D22 -> 4162
A23: ='RESOLUCIONES 2015'!A5863:H5863 | B23: 41516 | C23: 2 | D23: 42044 | E23: GIOVANA DUEÑAS PAREJA | G23: FECHA Y HORA DE SUSTENTACION | N23: =TODAY() -> 46206 | O23: ='RESOLUCIONES EPG'!$N23-'RESOLUCIONES EPG'!$D23 -> 4162
A24: ='RESOLUCIONES 2015'!A5874:H5874 | B24: 44346 | C24: 13 | D24: 42044 | E24: DEYRA SORAYA SUAREZ RAMOS | G24: DESIGNACION DE DICTAMINANTES | N24: =TODAY() -> 46206 | O24: ='RESOLUCIONES EPG'!$N24-'RESOLUCIONES EPG'!$D24 -> 4162
A25: ='RESOLUCIONES 2015'!A5880:H5880 | B25: 3470 | C25: 19 | D25: 42046 | E25: RAFAEL AQUIZE ESTRADA | G25: DESIGNACION DE DICTAMINANTES | N25: =TODAY() -> 46206 | O25: ='RESOLUCIONES EPG'!$N25-'RESOLUCIONES EPG'!$D25 -> 4160
A26: ='RESOLUCIONES 2015'!A5883:H5883 | B26: 3307 | C26: 22 | D26: 42046 | E26: LUIS ALBERTO BEJARANO JORDAN | G26: NOMBRAMIENTO DE ASESOR | N26: =TODAY() -> 46206 | O26: ='RESOLUCIONES EPG'!$N26-'RESOLUCIONES EPG'!$D26 -> 4160
A27: ='RESOLUCIONES 2015'!A5885:H5885 | B27: 3307 | C27: 24 | D27: 42046 | E27: LUIS ALBERTO BEJARANO JORDAN | G27: NOMBRAMIENTO DE ASESOR | N27: =TODAY() -> 46206 | O27: ='RESOLUCIONES EPG'!$N27-'RESOLUCIONES EPG'!$D27 -> 4160
A28: ='RESOLUCIONES 2015'!A5881:H5881 | B28: 1509 | C28: 20 | D28: 42046 | E28: CANSAYA ROMAN AYDEE | G28: SUBSANACION | N28: =TODAY() -> 46206 | O28: ='RESOLUCIONES EPG'!$N28-'RESOLUCIONES EPG'!$D28 -> 4160
A29: ='RESOLUCIONES 2015'!A5882:H5882 | B29: 686 | C29: 21 | D29: 42046 | E29: ANGULO CABRERA MARIA LUISA | G29: SUBSANACION | N29: =TODAY() -> 46206 | O29: ='RESOLUCIONES EPG'!$N29-'RESOLUCIONES EPG'!$D29 -> 4160
A30: ='RESOLUCIONES 2015'!A5886:H5886 | B30: 3001 | C30: 25 | D30: 42046 | E30: ANGEL MUÑOZ ARAGON | G30: NOMBRAMIENTO DE ASESOR | N30: =TODAY() -> 46206 | O30: ='RESOLUCIONES EPG'!$N30-'RESOLUCIONES EPG'!$D30 -> 4160
A31: ='RESOLUCIONES 2015'!A5884:H5884 | B31: 38421 | C31: 23 | D31: 42047 | E31: SALAS AYCHO NANCY VIOLETA | G31: SUBSANACION | N31: =TODAY() -> 46206 | O31: ='RESOLUCIONES EPG'!$N31-'RESOLUCIONES EPG'!$D31 -> 4159
A32: ='RESOLUCIONES 2015'!A5890:H5890 | B32: 3007 | C32: 29 | D32: 42047 | E32: RENAN RAMIREZ VARGAS | G32: DESIGNACION DE DICTAMINANTES | N32: =TODAY() -> 46206 | O32: ='RESOLUCIONES EPG'!$N32-'RESOLUCIONES EPG'!$D32 -> 4159
A33: ='RESOLUCIONES 2015'!A5889:H5889 | C33: 28 | D33: 42047 | E33: PROCESO ADMISION | G33: COMISION DEL PROCESO DE ADMISION 2015-1 | N33: =TODAY() -> 46206 | O33: ='RESOLUCIONES EPG'!$N33-'RESOLUCIONES EPG'!$D33 -> 4159
A34: ='RESOLUCIONES 2015'!A5888:H5888 | B34: 27782 | C34: 27 | D34: 42047 | E34: LUIS GHANDY ROJAS ARIAS | G34: INSCRIPCION DE TEMA DE TESIS | N34: =TODAY() -> 46206 | O34: ='RESOLUCIONES EPG'!$N34-'RESOLUCIONES EPG'!$D34 -> 4159
A35: ='RESOLUCIONES 2015'!A5887:H5887 | B35: 4202 | C35: 26 | D35: 42047 | E35: JOSE ANTONIO ALANYA RICALDE | G35: DESIGNACION DE DICTAMINANTES | N35: =TODAY() -> 46206 | O35: ='RESOLUCIONES EPG'!$N35-'RESOLUCIONES EPG'!$D35 -> 4159
A36: ='RESOLUCIONES 2015'!A5892:H5892 | B36: 44824 | C36: 31 | D36: 42048 | E36: JAVIER ORLANDO CUNZA VALDEIGLESIAS | F36: Actualizacion | G36: DESIGNACION DE DICTAMINANTES | N36: =TODAY() -> 46206 | O36: ='RESOLUCIONES EPG'!$N36-'RESOLUCIONES EPG'!$D36 -> 4158
A37: ='RESOLUCIONES 2015'!A5891:H5891 | B37: 27782 | C37: 30 | D37: 42052 | E37: MARIA ROSA GAMIO VEGA CENTENO | G37: DESIGNACION DE DICTAMINANTES | N37: =TODAY() -> 46206 | O37: ='RESOLUCIONES EPG'!$N37-'RESOLUCIONES EPG'!$D37 -> 4154
A38: ='RESOLUCIONES 2015'!A5893:H5893 | B38: 36884 | C38: 32 | D38: 42052 | E38: JOSE LUIS GONZALES AVENDAÑO | G38: MODIFICAR LA RESOLUCION 232-2014/EPG-UAC | N38: =TODAY() -> 46206 | O38: ='RESOLUCIONES EPG'!$N38-'RESOLUCIONES EPG'!$D38 -> 4154
A39: ='RESOLUCIONES 2015'!A5895:H5895 | B39: 3854 | C39: 34 | D39: 42053 | E39: MARIA LILIANA PEÑA FARFAN | G39: DESIGNACION DE DICTAMINANTES | N39: =TODAY() -> 46206 | O39: ='RESOLUCIONES EPG'!$N39-'RESOLUCIONES EPG'!$D39 -> 4153
A40: ='RESOLUCIONES 2015'!A5896:H5896 | B40: 5328 | C40: 35 | D40: 42053 | E40: JUAN DIEGO PALOMINO DELGADO | G40: DESIGNACION DE DICTAMINANTES | N40: =TODAY() -> 46206 | O40: ='RESOLUCIONES EPG'!$N40-'RESOLUCIONES EPG'!$D40 -> 4153
A41: ='RESOLUCIONES 2015'!A5894:H5894 | B41: 3671 | C41: 33 | D41: 42053 | E41: CARLOS ALBERTO VALENCIA MARTINEZ | G41: JURADO DICTAMINADOR PARA SUTENTACION | N41: =TODAY() -> 46206 | O41: ='RESOLUCIONES EPG'!$N41-'RESOLUCIONES EPG'!$D41 -> 4153
A42: ='RESOLUCIONES 2015'!A5897:H5897 | C42: 36 | D42: 42059 | E42: INGRESANTES ADMISION 2015 | G42: INGRESANTES A LA MAESTRIA EN DERECHO CONSTITUCIONAL | N42: =TODAY() -> 46206 | O42: ='RESOLUCIONES EPG'!$N42-'RESOLUCIONES EPG'!$D42 -> 4147
A43: ='RESOLUCIONES 2015'!A5898:H5898 | C43: 37 | D43: 42059 | E43: INGRESANTES ADMISION 2015 | G43: INGRESANTES A LA MAESTRIA EN ADMINISTRACION DE NEGOCIOS | N43: =TODAY() -> 46206 | O43: ='RESOLUCIONES EPG'!$N43-'RESOLUCIONES EPG'!$D43 -> 4147
A44: ='RESOLUCIONES 2015'!A5899:H5899 | C44: 38 | D44: 42059 | E44: INGRESANTES ADMISION 2015 | G44: INGRESANTES A LA MAESTRIA EN ESTADISTICA E INVESTIGACION CIENTIFICA | N44: =TODAY() -> 46206 | O44: ='RESOLUCIONES EPG'!$N44-'RESOLUCIONES EPG'!$D44 -> 4147
...

Sheet CONSEJO EPG 2025
A1: RESOLUCIONES EMITIDAS CONSEJO DE LA ESCUELA 2025
A2: N° SOLICITUD | B2: RESOL. N° | C2: FECHA | D2: NOMBRES Y APELLIDOS | E2: CODIGO2 | F2: TIPO DE RESOLUCION | G2: Observaciones | H2: RESOLUCION 2
B3: 1 | C3: 45931 | D3: APROBAR las Líneas de Investigación de la Escuela de Posgrado de la Universidad Andina del Cusco | F3: APROBAR las Líneas de Investigación
A4: Enviado | B4: 2 | C4: 45964 | D4: NINATAYPE MAMANI LADISLAO MAURICE | E4: 017200103K | F4: ELEVAR AL VRAC | G4: MAESTRO EN DOCENCIA UNIVERSITARIA
B5: 3
B6: 4 | C6: 45966 | D6: APROBAR el Formato 2: Instrumento de Evaluación de Planes Curriculares de la Escuela de Posgrado
B7: 5 | C7: 45966 | D7: APROBAR la Estructura del Plan Curricular para la Escuela de Posgrado
B8: 6 | C8: 45966 | D8: APROBAR el Perfil de Ingreso a la Escuela de Posgrado de la Universidad Andina del Cusco
B9: 7 | C9: 45966 | D9: APROBAR la implementación piloto del Procedimiento de Evaluación del Desempeño Académico Docente
B10: 8 | C10: 45967 | D10: ESTRADA PANTIA JOSÉ LUIS | E10: 019100007H | F10: ELEVAR AL VRAC | G10: DOCTOR EN CIENCIAS DE LA EDUCACIÓN
A11: Enviado | B11: 9 | C11: 45967 | D11: NEGRON CALVO LISARDO | E11: 45967 | F11: ELEVAR AL VRAC | G11: DOCTOR EN CIENCIAS DE LA EDUCACIÓN
A12: Enviado | B12: 10 | C12: 45967 | D12: MEJIA SURCO JAIME | E12: 018200216I | F12: ELEVAR AL VRAC | G12: MAESTRO EN DERECHO CIVIL Y COMERCIAL
A13: Enviado | B13: 11 | C13: 45967 | D13: VALENZUELA CARRASCO JUAN FRANKS | E13: 021200171J | F13: ELEVAR AL VRAC | G13: MAESTRO EN INGENIERÍA CIVIL CON MENCIÓN EN ESTRUCTURAS | H13: Falta sello
A14: Enviado | B14: 12 | C14: 45967 | D14: TORRE CALDERON EDGAR | E14: 018100026C | F14: ELEVAR AL VRAC | G14: MAESTRO EN DOCENCIA UNIVERSITARIA
A15: Enviado | B15: 13 | C15: 45967 | D15: CORNEJO ROJAS MILENKA | E15: 019300040I | F15: ELEVAR AL VRAC | G15: MAESTRO EN DOCENCIA UNIVERSITARIA
A16: Enviado | B16: 14 | C16: 45967 | D16: MUJICA SANCHEZ RAQUEL LIBERTAD | E16: 019200396F | F16: ELEVAR AL VRAC | G16: MAESTRO EN DOCENCIA UNIVERSITARIA
B17: 15 | C17: 45974 | D17: ESTRADA PANTIA JOSÉ LUIS | E17: 019100007H | F17: ELEVAR AL VRAC | G17: DOCTOR EN CIENCIAS DE LA EDUCACIÓN
A18: Enviado | B18: 16 | C18: 45974 | D18: CUELLAR RADO AMILCAR | E18: 019300009D | F18: ELEVAR AL VRAC | G18: MAESTRO EN DERECHO CONSTITUCIONAL
A19: Enviado | B19: 17 | C19: 45974 | D19: HOLGADO CARDENAS YENY FRANCY | E19: 021300009J | F19: ELEVAR AL VRAC | G19: MAESTRA EN ADMINISTRACIÓN DE NEGOCIOS
A20: Enviado | B20: 18 | C20: 45979 | D20: TTITO LAURA PRISCILIANO | E20: 015101443J | F20: ELEVAR AL VRAC | G20: MAESTRO EN CONTABILIDAD CON MENCIÓN EN AUDITORÍA Y CONTROL INTERNO
B21: 19 | C21: 45989 | D21: cambio de locación administrativa de la Escuela de Posgrado de la Universidad Andina del Cusco, desde la sede ubicada en Av. El Sol
B22: 20 | C22: 45989 | D22: APROBAR la Directiva N.° 001-2025-UAC-EPG | F22: “Implementación del Nuevo Sistema Académico Semestral de la Escuela de Posgrado”
B23: 21 | C23: 45989 | D23: Plantillas de Planes de Estudio para los programas de Maestría y Doctorado | F23: Plantillas de Planes de Estudio
A24: Enviado | B24: 22 | C24: 45994 | D24: CHOQUEVILCA LIRA WALTER FLORENCIO | E24: 015101538K | F24: ELEVAR AL VRAC | G24: DOCTOR EN MEDIO AMBIENTE Y DESARROLLO SOSTENIBLE.
A25: Enviado | B25: 23 | C25: 45994 | D25: CASTILLO ANCHARI LIBIA | E25: 020100005A | F25: ELEVAR AL VRAC | G25: DOCTORA EN CIENCIAS DE LA EDUCACIÓN
A26: Enviado | B26: 24 | C26: 45994 | D26: VARGAS GONZALES REIDY RENZO | E26: 019200213I | F26: ELEVAR AL VRAC | G26: DOCTOR EN CIENCIAS DE LA SALUD
A27: Enviado | B27: 25 | C27: 45994 | D27: PANOCCA MERMA CLAUDIO ZENOBIO | E27: 018100018K | F27: ELEVAR AL VRAC | G27: MAESTRO EN DOCENCIA UNIVERSITARIA
A28: Enviado | B28: 26 | C28: 45994 | D28: CHALCO SUAREZ JESSICA ELIZABETH | E28: 015101349C | F28: ELEVAR AL VRAC | G28: MAESTRA EN ESTADÍSTICA E INVESTIGACIÓN CIENTÍFICA
A29: Enviado | B29: 27 | C29: 45996 | D29: CONDORI PAUCCARA JOSE | E29: 022300033G | F29: ELEVAR AL VRAC | G29: DOCTOR EN CIENCIAS DE LA EDUCACIÓN.
A30: Enviado | B30: 28 | C30: 45996 | D30: VALENZUELA FARFAN RONNY | E30: 023200081I | F30: ELEVAR AL VRAC | G30: MAESTRO EN DOCENCIA UNIVERSITARIA.
A31: Enviado | B31: 29 | C31: 45996 | D31: CAMARENA QUISPE ROLANDO JOSE | E31: 021200033F | F31: ELEVAR AL VRAC | G31: DOCTOR EN DERECHO
B32: 30 | C32: 46002 | D32: 1ER PROGRAMA DE AUDITORÍA INTERNA DE LA ESCUELA DE POSGRADO – ISO 9001:2015
A33: Enviado | B33: 31 | C33: 46007 | D33: APROBAR la Misión y Visión de la Escuela de Posgrado | F33: ELEVAR AL VRAC
A34: Enviado | B34: 32 | C34: 46008 | D34: MANGO RAYME STEFANY BARBARA | E34: 023200065C | F34: ELEVAR AL VRAC | G34: MAESTRA EN DOCENCIA UNIVERSITARIA
B35: 33
B36: 34
B37: 35
B38: 36
B39: 37

Sheet CONSEJO EPG 2026
A1: RESOLUCIONES EMITIDAS CONSEJO DE LA ESCUELA 2025
A2: N° SOLICITUD | B2: RESOL. N° | C2: FECHA | D2: NOMBRES Y APELLIDOS | E2: CODIGO | F2: Observaciones | G2: TIPO DE RESOLUCION | H2: RESOLUCION 2
A3: Enviado | B3: -32 | C3: 46008 | D3: MANGO RAYME STEFANY BARBARA | E3: 023200065C | F3: MAESTRA EN DOCENCIA UNIVERSITARIA | G3: ELEVAR AL VRAC
A4: Enviado | B4: 1 | C4: 46076 | D4: MONGE NAVEROS YUDI | E4: 022300039E | F4: DOCTORA EN CIENCIAS DE LA EDUCACIÓN | G4: ELEVAR AL VRAC
A5: Enviado | B5: 2 | C5: 46076 | D5: CCARITA YUCRA JUVENAL JULIO | E5: 013200914B | F5: MAESTRO EN DERECHO CONSTITUCIONAL | G5: ELEVAR AL VRAC
A6: Enviado | B6: 3 | C6: 46076 | D6: APAZA DURAN ALAN JIMY | E6: 020300035A | F6: DOCTOR EN CIENCIAS DE LA SALUD | G6: ELEVAR AL VRAC
A7: Enviado | B7: 4 | C7: 46076 | D7: CARHUAS CUADROS TESSY | E7: 015101388I | F7: MAESTRA EN SEGURIDAD INDUSTRIAL Y MEDIO AMBIENTE | G7: ELEVAR AL VRAC
A8: Enviado | B8: 5 | C8: 46076 | D8: QUINTANILLA PALOMINO HARRY KEVIN | E8: 018300221D | F8: MAESTRO EN DERECHO CONSTITUCIONAL | G8: ELEVAR AL VRAC
A9: Enviado | B9: 6 | C9: 46076 | D9: TAIPE PILA DAMNA SHAREM | E9: 023200118J | F9: MAESTRA EN SEGURIDAD INDUSTRIAL Y MEDIO AMBIENTE | G9: ELEVAR AL VRAC
A10: Enviado | B10: 7 | C10: 46076 | D10: PALOMINO APARICIO DIANA | E10: 017200127G | F10: MAESTRA EN ADMINISTRACIÓN DE NEGOCIOS | G10: ELEVAR AL VRAC
A11: Enviado | B11: 8 | C11: 46076 | D11: GONZALES HUANCA NANCY | E11: 019200277G | F11: DOCTORA EN ADMINISTRACIÓN | G11: ELEVAR AL VRAC
A12: Enviado | B12: 9 | C12: 46076 | D12: SOTA PULIDO PILAR MARGOT | E12: 019200356D | F12: MAESTRA EN DOCENCIA UNIVERSITARIA | G12: ELEVAR AL VRAC
A13: Enviado | B13: 10 | C13: 46076 | D13: ROJAS BENAVIDES JIMENA ALONDRA | E13: 023200115K | F13: MAESTRA EN SEGURIDAD INDUSTRIAL Y MEDIO AMBIENTE | G13: ELEVAR AL VRAC
A14: Enviado | B14: 11 | C14: 46076 | D14: OLARTE MONTES NESTOR ABEL | E14: 013200949K | F14: MAESTRO EN DERECHO DEL TRABAJO Y DE LA SEGURIDAD SOCIAL | G14: ELEVAR AL VRAC
A15: Enviado | B15: 12 | C15: 46076 | D15: DE LOS RIOS GUZMAN ABRAHAM | E15: 014101616B | F15: MAESTRO EN SEGURIDAD INDUSTRIAL Y MEDIO AMBIENTE | G15: ELEVAR AL VRAC
B16: 13 | C16: 46078 | D16: reconformación del COMITÉ DE CALIDAD DE LA ESCUELA DE POSGRADO
B17: 14 | C17: 46078 | D17: Comité de Evaluación e Innovación Curricular de la EPG
B18: 15
B19: 16
B20: 17
B21: 18 | C21: 46111 | D21: LOAIZA VILCHEZ CINTIA LICETH | E21: 013201057F | F21: MAESTRA EN CIENCIAS ESTOMATOLÓGICAS | G21: ELEVAR AL VRAC
B22: 19 | C22: 46111 | D22: AGUILAR VELARDE LUIS ERNESTO | E22: 017200192C | F22: MAESTRO EN DERECHO REGISTRAL Y NOTARIAL | G22: ELEVAR AL VRAC
B23: 20 | C23: 46111 | D23: SERNAQUE FERNANDEZ PAULA BENANCIA | E23: 023200013C | F23: DOCTORA EN CIENCIAS DE LA EDUCACIÓN | G23: ELEVAR AL VRAC
B24: 21 | C24: 46111 | D24: GAMARRA MONTAÑEZ CARLOS ERNESTO | E24: 019100134J | F24: MAESTRO EN SEGURIDAD INDUSTRIAL Y MEDIO AMBIENTE. | G24: ELEVAR AL VRAC
B25: 22 | C25: 46111 | D25: LLACTA TOVAR SANDRA FAVIOLA | E25: 019300049F | F25: MAESTRA EN DOCENCIA UNIVERSITARIA | G25: ELEVAR AL VRAC
B26: 23 | C26: 46111 | D26: COSIO MUÑOZ JUAN | E26: 020300137I | F26: MAESTRO EN DERECHO CONSTITUCIONAL | G26: ELEVAR AL VRAC
B27: 24 | C27: 46111 | D27: FLOREZ RONDAN VERONIKA STEPHANIE | E27: 025102172H | F27: DOCTORA EN CIENCIAS DE LA SALUD | G27: ELEVAR AL VRAC
B28: 25 | C28: 46111 | D28: MOZO AYMA GABRIEL | E28: 013201094I | F28: DOCTOR EN CIENCIAS DE LA EDUCACIÓN | G28: ELEVAR AL VRAC
B29: 26 | C29: 46111 | D29: MENDOZA VALENZUELA JUBENAL | E29: 020300018J | F29: DOCTOR EN CIENCIAS DE LA EDUCACIÓN | G29: ELEVAR AL VRAC
B30: 27 | C30: 46111 | D30: ROMERO COPACONDORI FIORELA AYDE | E30: 019300166B | F30: MAESTRA EN ADMINISTRACIÓN DE NEGOCIOS | G30: ELEVAR AL VRAC
B31: 28 | C31: 46111 | D31: ALVES CHOQUE EDISON ALAN | E31: 018300039A | F31: DOCTORADO EN CIENCIAS DE LA EDUCACIÓN | G31: ELEVAR AL VRAC
B32: 29 | C32: 46111 | D32: YABAR HERMOZA GUSTAVO ENRIQUE | E32: 019100123H | F32: MAESTRÍA EN DERECHO CONSTITUCIONAL | G32: ELEVAR AL VRAC
... B48: 45 | C48: 46111 | D48: SOTO HERMOZA MIRIAN | E48: 019300072H | F48: MAESTRÍA EN DOCENCIA UNIVERSITARIA | G48: ELEVAR AL VRAC
B49: 46 | C49: 46111 | D49: APROBAR el 'PLAN DE ACTIVIDADES DE MEJORA CONTINUA (PAMC) SEMESTRE ACADÉMICO 2026-I'
B50: 47
B51: 48
B52: 49
B53: 50
B54: 51
B55: 52
...

Sheet RESOLUCIONES 2026
A1: RESOLUCIONES EMITIDAS 2026 | J1: CARGOS
A2: N° SOLICITUD | B2: RESOL. N° | C2: FECHA | D2: NOMBRES Y APELLIDOS | E2: CODIGO2 | F2: TIPO DE RESOLUCION | G2: Observaciones | H2: RESOLUCION 2 | I2: Columna1 | J2: Programa | K2: DICTAMEN 2 | L2: CARGO 3 | M2: CARGO 4 | N2: CARGO 5 | O2: CARGO 6 | P2: Columna 1 | Q2: Columna 2 | R2: Columna 3 | S2: Columna 4
A3: Enviado | B3: 1 | C3: 46057 | D3: BUSTAMANTE QUISPE SUSAN KAREN | E3: 017300033D | F3: DICTAMEN DE PROYECTO DE TESIS
A4: Enviado | B4: 2 | C4: 46057 | D4: HUACAC MOSQUEIRA LAURA MILDRED | E4: 014101526C | F4: DICTAMEN DE PROYECTO DE TESIS | G4: PROYECTO ENVIADO MAL
A5: Enviado | B5: 3 | C5: 46057 | D5: GARCÍA CUSIHUALLPA RENATO | E5: 016102217B | F5: DICTAMEN DE PROYECTO DE TESIS
A6: Enviado | B6: 4 | C6: 46057 | D6: ESPINOZA CAÑARI HENRY EDWARD | E6: 014101617I | F6: DICTAMEN DE PROYECTO DE TESIS
A7: Enviado | B7: 5 | C7: 46057 | D7: MEJIA GALICIA WALTER | E7: 016102223B | F7: DICTAMEN DE PROYECTO DE TESIS
A8: Enviado | B8: 6 | C8: 46057 | D8: CARRION ABOLLANEDA RICHARD | E8: 019200338F | F8: INSCRIPCION DE PROYECTO | G8: DE FORMA
A9: Enviado | B9: 7 | C9: 46057 | D9: MAMANI APAZA IGNACIO | E9: 016102370E | F9: INSCRIPCION DE PROYECTO | G9: DE FORMA
A10: Enviado | B10: 8 | C10: 46057 | D10: TAIPE PARDO FREDY | E10: 018100075D | F10: INSCRIPCION DE PROYECTO | G10: DE FORMA
A11: Enviado | B11: 9 | C11: 46057 | D11: VIGURIA SALAZAR MICHAEL | E11: 020300228D | F11: INSCRIPCION DE PROYECTO | G11: DE FORMA
A12: Enviado | B12: 10 | C12: 46057 | D12: ACO CORRALES MARGOT MARITZA | E12: 018300043I | F12: INSCRIPCION DE PROYECTO | G12: ERROR MATERIAL
A13: Enviado | B13: 11 | C13: 46057 | D13: VENERO MORALES JORIEN | E13: 018100050A | F13: INSCRIPCION DE PROYECTO
A14: Enviado | B14: 12 | C14: 46057 | D14: CASTILLO CONTRERAS JESUSA | E14: 018100006B | F14: INSCRIPCION DE PROYECTO
A15: Enviado | B15: 13 | C15: 46057 | D15: CASTRO LOAYZA JAMILY SDENKA | E15: 013201043E | F15: INSCRIPCION DE PROYECTO
A16: Enviado | B16: 14 | C16: 46057 | D16: OLIVARES TAPIA YENY MARLENY | E16: 16201415G | F16: INSCRIPCION DE PROYECTO
A17: Enviado | B17: 15 | C17: 46057 | D17: TINEO TUEROS MIRELLA PAMELA | E17: 017200079B | F17: INSCRIPCION DE PROYECTO
A18: Enviado | B18: 16 | C18: 46057 | D18: PALOMINO OQUENDO WALTER VICENTE | E18: 012200959G | F18: DICTAMEN DE PROYECTO DE TESIS
A19: Enviado | B19: 17 | C19: 46069 | D19: HOLGUIN CURI MILUVSKA JHAKELINNE | E19: 024101486J | F19: DICTAMEN DE PROYECTO DE TESIS
A20: Enviado | B20: 18 | C20: 46069 | D20: BAÑON RAMOS LUCI VIRGINIA | E20: 023200050F | F20: DICTAMEN DE TESIS | G20: CAMBIO DE DICTAMINANTE
A21: Enviado | B21: 19 | C21: 46072 | D21: TRESIERRA PANTIGOZO ABEL | E21: 013201097H | F21: APTO AL GRADO
A22: Enviado | B22: 20 | C22: 46072 | D22: TEVES ARCCATA CIRILA MONICA | E22: 18300059B | F22: INSCRIPCION DE PROYECTO
A23: Enviado | B23: 21 | C23: 46072 | D23: BENITES FERNANDEZ GABRIEL JESUS | E23: 017300191I | F23: INSCRIPCION DE PROYECTO
A24: Enviado | B24: 22 | C24: 46072 | D24: SANTOS SALCEDO RICARDO ALVARO | E24: 019200223D | F24: DICTAMEN DE PROYECTO DE TESIS | G24: CAMBIO DE DICTAMINANTE
A25: Enviado | B25: 23 | C25: 46072 | D25: DURAN QUISPE LUZ BRENDA | E25: 019200310D | F25: DICTAMEN DE PROYECTO DE TESIS | G25: CAMBIO DE DICTAMINANTE
A26: Enviado | B26: 24 | C26: 46072 | D26: CCOA CHALLCO ELOY | E26: 015101348G | F26: DICTAMEN DE PROYECTO DE TESIS
A27: Enviado | B27: 25 | C27: 46072 | D27: ROJAS CESPEDES ROBERTO CARLOS | E27: 017200042A | F27: APTO AL GRADO
A28: Enviado | B28: 26 | C28: 46072 | D28: ARREDONDO GALLEGOS ROY ROGER | E28: 023300076G | F28: APTO AL GRADO
A29: Enviado | B29: 27 | C29: 46072 | D29: ROMERO QUISPE INGA FANNY CAROLINA | E29: 015201395G | F29: DICTAMEN DE PROYECTO DE TESIS
A30: Enviado | B30: 28 | C30: 46072 | D30: DELGADO MARTINEZ GISELY | E30: 018300003G | F30: DICTAMEN DE PROYECTO DE TESIS
A31: Enviado | B31: 29 | C31: 46072 | D31: CAHUASCANCO MONTALVO YHULDER ANTHONY | E31: 020300131k | F31: AMPLIACIÓN DE INSCRIPCIÓN
A32: Enviado | B32: 30 | C32: 46073 | D32: MENDOZA NINA RENATO HECTOR | E32: 019200144G | F32: FIJAR FECHA Y HORA | G32: 27 de febrero de 2026 a 16:00 | H32: Se envia observaciones de sustentacion
A33: Enviado | B33: 31 | C33: 46073 | D33: BARRANTES YUCRA ANGEL | E33: 020100082F | F33: FIJAR FECHA Y HORA | G33: 27 de febrero de 2026 a 18:00 | H33: Se envia observaciones de sustentacion
A34: Enviado | B34: 32 | C34: 46077 | D34: ROJAS VEGA CENTENO GABRIELA INGRID | E34: 023300199A | F34: APTO AL GRADO
B35: 33 | C35: 46077 | D35: JANQUI ESQUIVEL LEONIDAS | E35: 016102185C | F35: APTO AL GRADO | G35: Centro de Idiomas, sin DJ
B36: 34 | C36: 46077 | D36: NUÑEZ RAMIREZ ANGEL | E36: 014101531G | F36: APTO AL GRADO | G36: Centro de Idiomas
A37: Enviado | B37: 35 | C37: 46077 | D37: ALMANZA HUAYLLANI BRENDA XIMENA | E37: 023200016B | F37: APTO AL GRADO
A38: Enviado | B38: 36 | C38: 46077 | D38: FERNANDEZ BACA PAREJA ROMULO MIGUEL | E38: 016201395F | F38: APTO AL GRADO
A39: Enviado | B39: 37 | C39: 46077 | D39: SILVA BELTRAN EDUARDO | E39: 022100051A | F39: APTO AL GRADO
B40: 38 | C40: 46077 | D40: UMERES MENA EDWIN | E40: 015101560F | F40: APTO AL GRADO | G40: Centro de Idiomas
...

Sheet RESOLUCIONES 2025
A1: RESOLUCIONES EMITIDAS 2025 | J1: CARGOS
A2: N° SOLICITUD | B2: RESOL. N° | C2: FECHA | D2: NOMBRES Y APELLIDOS | E2: CODIGO2 | F2: TIPO DE RESOLUCION | G2: Observaciones | H2: RESOLUCION 2 | I2: Columna1 | J2: Programa | K2: DICTAMEN 2 | L2: CARGO 3 | M2: CARGO 4 | N2: CARGO 5 | O2: CARGO 6
B3: =ROW() - ROW('RESOLUCIONES 2025'!$B$2) - 44 -> -43 | C3: 45659 | D3: CCORIMANYA USCA ERIKA ELIZABETH | E3: 024101530I | F3: AUTORIZAR matrícula de curso pendiente
B4: =ROW() - ROW('RESOLUCIONES 2025'!$B$2) - 44 -> -42 | C4: 45659 | D4: JORDAN ZEGARRA RAIKO | E4: 023300114F | F4: AUTORIZAR matrícula de curso pendiente | K4: pro
B5: =ROW() - ROW('RESOLUCIONES 2025'!$B$2) - 44 -> -41 | C5: 45666 | D5: CHRISTIAN JOHNSON CARRASCO AHEN | E5: 025102132F | F5: CONVALIDACION
B6: =ROW() - ROW('RESOLUCIONES 2025'!$B$2) - 44 -> -40 | C6: 45666 | D6: CORDOVA CUSI ALEXANDER ULICES | E6: 025102134i | F6: CONVALIDACION
B7: =ROW() - ROW('RESOLUCIONES 2025'!$B$2) - 44 -> -39 | C7: 45666 | D7: SAENZ PERALTA MARCO ANTONIO | E7: 025102144D | F7: CONVALIDACION
B8: =ROW() - ROW('RESOLUCIONES 2025'!$B$2) - 44 -> -38 | C8: 45666 | D8: DIAZ HUILLCA ISAAC | E8: 025102135e | F8: CONVALIDACION
B9: =ROW() - ROW('RESOLUCIONES 2025'!$B$2) - 44 -> -37 | C9: 45666 | D9: HUALLPA CATUNTA EDILBERTO | E9: 025102136a | F9: CONVALIDACION
B10: =ROW() - ROW('RESOLUCIONES 2025'!$B$2) - 44 -> -36 | C10: 45666 | D10: HUAYLLANI VEGA EDGAR CIRILO | E10: 025102137H | F10: CONVALIDACION
B11: =ROW() - ROW('RESOLUCIONES 2025'!$B$2) - 44 -> -35 | C11: 45666 | D11: QUISPE INFANTES REYNALDO RICARDO | E11: 025102142A | F11: CONVALIDACION
B12: =ROW() - ROW('RESOLUCIONES 2025'!$B$2) - 44 -> -34 | C12: 45666 | D12: SERRANO TRUJILLO NALDA | E12: 025102146g | F12: CONVALIDACION
B13: =ROW() - ROW('RESOLUCIONES 2025'!$B$2) - 44 -> -33 | C13: 45666 | D13: OJEDA ORTEGA ESMERALDA MARIA | E13: 025102140I | F13: CONVALIDACION
B14: =ROW() - ROW('RESOLUCIONES 2025'!$B$2) - 44 -> -32 | C14: 45666 | D14: SÁNCHEZ CÓRDOVA MARIELA | E14: 025102145K | F14: CONVALIDACION
B15: =ROW() - ROW('RESOLUCIONES 2025'!$B$2) - 44 -> -31 | C15: 45666 | D15: VARGAS USCAMAYTA RINA | E15: 025102147C | F15: CONVALIDACION
B16: =ROW() - ROW('RESOLUCIONES 2025'!$B$2) - 44 -> -30 | C16: 45666 | D16: PANDIA YAÑEZ EDWARD JIMMY | E16: 025102190f | F16: CONVALIDACION
... B64: =ROW() - ROW('RESOLUCIONES 2025'!$B$2) - 44 -> 18 | C64: 45677 | D64: CASTILLO ARROSQUIPA GIOVANA | E64: 025102133B | F64: DECLARAR SIN EFECTO
B65: =ROW() - ROW('RESOLUCIONES 2025'!$B$2) - 44 -> 19 | C65: 45678 | D65: HERMOZA APAZA JUAN DIEGO | F65: RECTIFICACIÓN DEL PROMEDIO DE NOTAS | G65: TUPAYACHI SOTOMAYOR JHONNY
B66: =ROW() - ROW('RESOLUCIONES 2025'!$B$2) - 44 -> 20 | C66: 45678 | D66: LIRA APAZA VICTOR RAUL | F66: RECTIFICACIÓN DEL PROMEDIO DE NOTAS | G66: TUPAYACHI SOTOMAYOR JHONNY
B67: =ROW() - ROW('RESOLUCIONES 2025'!$B$2) - 44 -> 21 | C67: 45678 | D67: MELENDEZ PORTAL MARITZA NAYELI | F67: RECTIFICACIÓN DEL PROMEDIO DE NOTAS | G67: TUPAYACHI SOTOMAYOR JHONNY
B68: =ROW() - ROW('RESOLUCIONES 2025'!$B$2) - 44 -> 22 | C68: 45677 | D68: NINA RAMOS EDWIN RIDER | E68: 025101944G | F68: CONVALIDACION
B69: =ROW() - ROW('RESOLUCIONES 2025'!$B$2) - 44 -> 23 | C69: 45677 | D69: GIOVANA CASTILLO ARROSQUIPA | E69: 025102133B | F69: CONVALIDACION
B70: =ROW() - ROW('RESOLUCIONES 2025'!$B$2) - 44 -> 24 | C70: 45677 | D70: GALDOS BERRIO ILBERTO | E70: 025101927E | F70: CONVALIDACION
B71: =ROW() - ROW('RESOLUCIONES 2025'!$B$2) - 44 -> 25 | C71: 45684 | D71: MONTESINOS PALOMINO ARTEMIO | E71: 025102189H | F71: CONVALIDACION
B72: =ROW() - ROW('RESOLUCIONES 2025'!$B$2) - 44 -> 26 | C72: 45684 | D72: RUEDA VERA KATHERING DELFINA | E72: 025102143H | F72: CONVALIDACION
B73: =ROW() - ROW('RESOLUCIONES 2025'!$B$2) - 44 -> 27 | C73: 45684 | D73: PEREYRA SANCHEZ VILMA | E73: 025102141E | F73: CONVALIDACION
B74: =ROW() - ROW('RESOLUCIONES 2025'!$B$2) - 44 -> 28 | C74: 45684 | D74: MONTESINOS PALOMINO ARTEMIO | E74: 025102189H | F74: DEJAR SIN EFECTO RESOLUCIÓN N°00672025/EPG-UAC
B75: =ROW() - ROW('RESOLUCIONES 2025'!$B$2) - 44 -> 29 | C75: 45691 | D75: PARICOTO GARCIA ROXANA | E75: 018200042K | F75: DICTAMEN DE PROYECTO DE TESIS
B76: =ROW() - ROW('RESOLUCIONES 2025'!$B$2) - 44 -> 30 | C76: 45691 | D76: CASTAÑEDA AVENDAÑO OSCAR | E76: 019300035E | F76: DICTAMEN DE PROYECTO DE TESIS
B77: =ROW() - ROW('RESOLUCIONES 2025'!$B$2) - 44 -> 31 | C77: 45691 | D77: BAÑON RAMOS LUCI VIRGINIA | E77: 023200050F | F77: DICTAMEN DE PROYECTO DE TESIS
B78: =ROW() - ROW('RESOLUCIONES 2025'!$B$2) - 44 -> 32 | C78: 45691 | D78: LICONA ARIZABAL CESAR ROLANDO | E78: 015101274C | F78: DICTAMEN DE PROYECTO DE TESIS
B79: =ROW() - ROW('RESOLUCIONES 2025'!$B$2) - 44 -> 33 | C79: 45691 | D79: CUELLAR RADO AMILCAR | E79: 019300009D | F79: DICTAMEN DE PROYECTO DE TESIS
... B88: =ROW() - ROW('RESOLUCIONES 2025'!$B$2) - 44 -> 42 | C88: 45691 | D88: VALER CONTRERAS AIDA | E88: 022100019K | F88: APTO AL GRADO
B89: =ROW() - ROW('RESOLUCIONES 2025'!$B$2) - 44 -> 43 | C89: 45691 | D89: NUÑEZ DEL PRADO COLL ENRIQUE | E89: 020300083F | F89: NOMBRAMIENTO ASESOR | G89: CHACON SANCHEZ VICTOR
B90: =ROW() - ROW('RESOLUCIONES 2025'!$B$2) - 44 -> 44 | C90: 45691 | D90: MASIAS FIGUEROA ROXANA | E90: 018200037G | F90: NOMBRAMIENTO ASESOR | G90: GARETH DEL CASTILLO ESTRADA
B91: =ROW() - ROW('RESOLUCIONES 2025'!$B$2) - 44 -> 45 | C91: 45691 | D91: PEÑA ROSAS SILME | E91: 017300075I | F91: NOMBRAMIENTO ASESOR | G91: BERTOLT FERNANDO OCROS GUEVARA
B92: =ROW() - ROW('RESOLUCIONES 2025'!$B$2) - 44 -> 46 | C92: 45691 | D92: TTUPA CARBAJAL ANABEL TATIANA | E92: 018200246E | F92: NOMBRAMIENTO ASESOR | G92: BERTOLT FERNANDO OCROS GUEVARA
B93: =ROW() - ROW('RESOLUCIONES 2025'!$B$2) - 44 -> 47 | C93: 45691 | D93: VALENCIA GARCIA JULIO CESAR | E93: 017200081G | F93: NOMBRAMIENTO ASESOR | G93: LUIS ALBERTO CHIHUANTITO ABAL
B94: =ROW() - ROW('RESOLUCIONES 2025'!$B$2) - 44 -> 48 | C94: 45691 | D94: VARGAS ESPINOZA SONIA ENEIDA | E94: 018200027A | F94: NOMBRAMIENTO ASESOR | G94: Teodoro Huarhua Chipani
B95: =ROW() - ROW('RESOLUCIONES 2025'!$B$2) - 44 -> 49 | C95: 45691 | D95: MERINO OBESO GLENDA | E95: 023300118A | F95: NOMBRAMIENTO ASESOR | G95: ISAAC ENRIQUE CASTRO CUBA BARINEZA
...

Sheet RESOLUCIONES 2024
A1: RESOLUCIONES EMITIDAS 2024 | J1: CARGOS
A2: N° SOLICITUD | B2: RESOL. N° | C2: FECHA | D2: NOMBRES Y APELLIDOS | E2: CODIGO2 | F2: TIPO DE RESOLUCION | G2: Obaservaciones | H2: RESOLUCION 2 | I2: Columna1 | J2: HOY | K2: Excede 730 Dias2 | L2: CARGO 3 | M2: CARGO 4 | N2: CARGO 5 | O2: CARGO 6
A3: Enviado | B3: 1 | C3: 45294 | D3: GARCIA CUEVA MIHAIL FERDINAN | E3: 018200004A | F3: INSCRIPCION DE PROYECTO DE TESIS | J3: =TODAY() -> 46206 | K3: ='RESOLUCIONES 2024'!$C3-'RESOLUCIONES 2024'!$J3 -> -912
A4: Enviado | B4: 2 | C4: 45294 | D4: HUILLCA BACA MAURA FANY | E4: 015101433D | F4: INSCRIPCION DE PROYECTO DE TESIS | J4: =TODAY() -> 46206 | K4: ='RESOLUCIONES 2024'!$C4-'RESOLUCIONES 2024'!$J4 -> -912
A5: Enviado | B5: 3 | C5: 45294 | D5: MOZO AYMA GABRIEL | E5: 013201094I | F5: INSCRIPCION DE PROYECTO DE TESIS | J5: =TODAY() -> 46206 | K5: ='RESOLUCIONES 2024'!$C5-'RESOLUCIONES 2024'!$J5 -> -912
A6: Enviado | B6: 4 | C6: 45294 | D6: TAPIA DELGADO BHELU | E6: 017200078F | F6: INSCRIPCION DE PROYECTO DE TESIS | J6: =TODAY() -> 46206 | K6: ='RESOLUCIONES 2024'!$C6-'RESOLUCIONES 2024'!$J6 -> -912
A7: Enviado | B7: 5 | C7: 45295 | D7: TORRES QUISPE EILEEN | E7: 015101484H | F7: INSCRIPCION DE PROYECTO DE TESIS | J7: =TODAY() -> 46206 | K7: ='RESOLUCIONES 2024'!$C7-'RESOLUCIONES 2024'!$J7 -> -911
A8: Enviado | B8: 6 | C8: 45295 | D8: GUZMAN MEDINA ADDERLY ROOSEVELT | E8: 019300125D | F8: INSCRIPCION DE PROYECTO DE TESIS | J8: =TODAY() -> 46206 | K8: ='RESOLUCIONES 2024'!$C8-'RESOLUCIONES 2024'!$J8 -> -911
B9: 7 | C9: 45295 | D9: XV CURSO DE ACTUALIZACIÓN | F9: relación de estudiantes admitidos en el XV CURSO DEACTUALIZACIÓN | J9: =TODAY() -> 46206 | K9: ='RESOLUCIONES 2024'!$C9-'RESOLUCIONES 2024'!$J9 -> -911
A10: Enviado | B10: 8 | C10: 45301 | D10: ALVAREZ ARIAS CELINDA | E10: 019200176F | F10: NOMBRAMIENTO DE ASESOR | G10: AGUIRRE ESPINOZA EDWARDS JESUS | J10: =TODAY() -> 46206 | K10: ='RESOLUCIONES 2024'!$C10-'RESOLUCIONES 2024'!$J10 -> -905
A11: Enviado | B11: 9 | C11: 45301 | D11: ARIZACA CUSICUNA JORGE LUIS | E11: 019100026B | F11: NOMBRAMIENTO DE ASESOR | G11: MORANTE RIOS EDWARD ANIBAL | J11: =TODAY() -> 46206 | K11: ='RESOLUCIONES 2024'!$C11-'RESOLUCIONES 2024'!$J11 -> -905
A12: Enviado | B12: 10 | C12: 45301 | D12: RODRIGUEZ CÁRDENAS FREDDY | E12: 017200310F | F12: NOMBRAMIENTO DE ASESOR | G12: GONZALES CONDORI HARRY YEISON | J12: =TODAY() -> 46206 | K12: ='RESOLUCIONES 2024'!$C12-'RESOLUCIONES 2024'!$J12 -> -905
A13: Enviado | B13: 11 | C13: 45301 | D13: CABALLERO ALEGRIA FLOR MARITZA | E13: 020300130D | F13: NOMBRAMIENTO DE ASESOR | G13: ACO CORRALES EDER ARTURO | J13: =TODAY() -> 46206 | K13: ='RESOLUCIONES 2024'!$C13-'RESOLUCIONES 2024'!$J13 -> -905
A14: Enviado | B14: 12 | C14: 45301 | D14: MEZA FERNANDEZ SANDRA | E14: 018300146B | F14: NOMBRAMIENTO DE ASESOR | G14: ESTRADA SANCHEZ PAOLA | J14: =TODAY() -> 46206 | K14: ='RESOLUCIONES 2024'!$C14-'RESOLUCIONES 2024'!$J14 -> -905
A15: Enviado | B15: 13 | C15: 45301 | D15: ARIAS REINOSO MADELEINE | E15: 020300108I | F15: NOMBRAMIENTO DE ASESOR | G15: ESTRADA SANCHEZ PAOLA | J15: =TODAY() -> 46206 | K15: ='RESOLUCIONES 2024'!$C15-'RESOLUCIONES 2024'!$J15 -> -905
A16: Enviado | B16: 14 | C16: 45301 | D16: FLORES PALOMINO ADRIANA PAOLA | E16: 016102242G | F16: NOMBRAMIENTO DE ASESOR | G16: GONZALES CONDORI HARRY YEISON | J16: =TODAY() -> 46206 | K16: ='RESOLUCIONES 2024'!$C16-'RESOLUCIONES 2024'!$J16 -> -905
A17: Enviado | B17: 15 | C17: 45301 | D17: LLANOS MAMANI JUAN EVER | E17: 018300142G | F17: NOMBRAMIENTO DE ASESOR | G17: DE LA TORRE DUEÑAS CLETO | J17: =TODAY() -> 46206 | K17: ='RESOLUCIONES 2024'!$C17-'RESOLUCIONES 2024'!$J17 -> -905
A18: Enviado | B18: 16 | C18: 45301 | D18: FELIX FLORES WARNER HANS | E18: 016102095D | F18: NOMBRAMIENTO DE ASESOR | G18: DELGADO CAMACHO ALEJANDRO VLADIMIR | J18: =TODAY() -> 46206 | K18: ='RESOLUCIONES 2024'!$C18-'RESOLUCIONES 2024'!$J18 -> -905
A19: Enviado | B19: 17 | C19: 45301 | D19: FERREL SARMIENTO DIOMEDES NAPOLEON | E19: 019200256J | F19: NOMBRAMIENTO DE ASESOR | G19: AGUIRRE ESPINOZA EDWARDS JESUS | J19: =TODAY() -> 46206 | K19: ='RESOLUCIONES 2024'!$C19-'RESOLUCIONES 2024'!$J19 -> -905
A20: Enviado | B20: 18 | C20: 45301 | D20: BARRIENTOS ALVAREZ ELENA ROSA | E20: 019200127E | F20: NOMBRAMIENTO DE ASESOR | G20: ORTIZ DIAZ RENZO GUILLERMO | J20: =TODAY() -> 46206 | K20: ='RESOLUCIONES 2024'!$C20-'RESOLUCIONES 2024'!$J20 -> -905
A21: Enviado | B21: 19 | C21: 45301 | D21: AGUILAR CHACON LISBETH BERENICE | E21: 020100030F | F21: NOMBRAMIENTO DE ASESOR | G21: ESTRADA SANCHEZ PAOLA | J21: =TODAY() -> 46206 | K21: ='RESOLUCIONES 2024'!$C21-'RESOLUCIONES 2024'!$J21 -> -905
... A68: Enviado | B68: 66 | C68: 45309 | D68: FLOREZ OTAZU KARINA FIORELLA | E68: 019200190I | F68: NOMBRAMIENTO DE ASESOR | G68: JAYO SILVA CARLOS EDUARDO | J68: =TODAY() -> 46206 | K68: ='RESOLUCIONES 2024'!$C68-'RESOLUCIONES 2024'!$J68 -> -897
A69: Enviado | B69: 67 | C69: 45309 | D69: VILCAHUAMÁN MEJÍA RICHARD HÉCTOR | E69: 017200134C | F69: INSCRIPCION DE PROYECTO DE TESIS | J69: =TODAY() -> 46206 | K69: ='RESOLUCIONES 2024'!$C69-'RESOLUCIONES 2024'!$J69 -> -897
A70: Enviado | B70: 68 | C70: 45309 | D70: SERNAQUE FERNANDEZ PAULA BENANCIA | E70: 023200013C | F70: NOMBRAMIENTO DE ASESOR | G70: AGUIRRE ESPINOZA EDWARDS JESUS | J70: =TODAY() -> 46206 | K70: ='RESOLUCIONES 2024'!$C70-'RESOLUCIONES 2024'!$J70 -> -897
A71: Enviado | B71: 69 | C71: 45309 | D71: ORMACHEA MEJIA MARIO JESUS | E71: 023200007C | F71: NOMBRAMIENTO DE ASESOR | G71: MELENDREZ VELASCO ELIAS | J71: =TODAY() -> 46206 | K71: ='RESOLUCIONES 2024'!$C71-'RESOLUCIONES 2024'!$J71 -> -897
A72: Enviado | B72: 70 | C72: 45310 | D72: MONTES PEDRAZA ROSA MARIA | E72: 019200262J | F72: INSCRIPCION DE PROYECTO DE TESIS | J72: =TODAY() -> 46206 | K72: ='RESOLUCIONES 2024'!$C72-'RESOLUCIONES 2024'!$J72 -> -896
A73: Enviado | B73: 71 | C73: 45316 | D73: MENDOZA LOAYZA IVAN | E73: 018100066E | F73: NOMBRAMIENTO DE ASESOR | G73: MORANTE RIOS EDWARD ANIBAL | J73: =TODAY() -> 46206 | K73: ='RESOLUCIONES 2024'!$C73-'RESOLUCIONES 2024'!$J73 -> -890
A74: Enviado | B74: 72 | C74: 45316 | D74: LICONA ARIZABAL CESAR ROLANDO | E74: 015101274C | F74: NOMBRAMIENTO DE ASESOR | G74: ALVIZ PAZOS SUSI | J74: =TODAY() -> 46206 | K74: ='RESOLUCIONES 2024'!$C74-'RESOLUCIONES 2024'!$J74 -> -890
A75: Enviado | B75: 73 | C75: 45316 | D75: FERNANDEZ SALCEDO JOSE LUIS | E75: 023200003H | F75: NOMBRAMIENTO DE ASESOR | G75: AGUIRRE ESPINOZA EDWARDS JESUS | J75: =TODAY() -> 46206 | K75: ='RESOLUCIONES 2024'!$C75-'RESOLUCIONES 2024'!$J75 -> -890
A76: Enviado | B76: 74 | C76: 45316 | D76: LASTEROS HOLGADO YOHN AUGUSTO | E76: 023200006G | F76: NOMBRAMIENTO DE ASESOR | G76: AGUIRRE ESPINOZA EDWARDS JESUS | J76: =TODAY() -> 46206 | K76: ='RESOLUCIONES 2024'!$C76-'RESOLUCIONES 2024'!$J76 -> -890
A77: Enviado | B77: 75 | C77: 45316 | D77: QUISPE CHOQQUE CESAR AUGUSTO | E77: 023200009F | F77: NOMBRAMIENTO DE ASESOR | G77: AGUIRRE ESPINOZA EDWARDS JESUS | J77: =TODAY() -> 46206 | K77: ='RESOLUCIONES 2024'!$C77-'RESOLUCIONES 2024'!$J77 -> -890
A78: Enviado | B78: 76 | C78: 45316 | D78: RAMOS CANDIA EUSTAQUIO | E78: 023200010D | F78: NOMBRAMIENTO DE ASESOR | G78: AGUIRRE ESPINOZA EDWARDS JESUS | J78: =TODAY() -> 46206 | K78: ='RESOLUCIONES 2024'!$C78-'RESOLUCIONES 2024'!$J78 -> -890
A79: Enviado | B79: 77 | C79: 45316 | D79: HERMOZA GRANADINO GIOVANNA GIANINA | E79: 015101272K | F79: NOMBRAMIENTO DE ASESOR | G79: ALVIZ PAZOS SUSI | J79: =TODAY() -> 46206 | K79: ='RESOLUCIONES 2024'!$C79-'RESOLUCIONES 2024'!$J79 -> -890
A80: Enviado | B80: 78 | C80: 45316 | D80: CAHUASCANCO MONTALVO YHULDER ANTHONY | E80: 020300131K | F80: INSCRIPCION DE PROYECTO DE TESIS | J80: =TODAY() -> 46206 | K80: ='RESOLUCIONES 2024'!$C80-'RESOLUCIONES 2024'!$J80 -> -890
A81: Enviado | B81: 79 | C81: 45316 | D81: GARCIA ALATRISTA FABIOLA PILAR | E81: 022300049K | F81: DEJAR SIN EFECTO | J81: =TODAY() -> 46206 | K81: ='RESOLUCIONES 2024'!$C81-'RESOLUCIONES 2024'!$J81 -> -890
A82: Enviado | B82: 80 | C82: 45323 | D82: HUMPIRE CASTRO ROY ANDY | E82: 022300007F | F82: DICTAMEN DE PROYECTO DE TESIS | J82: =TODAY() -> 46206 | K82: ='RESOLUCIONES 2024'!$C82-'RESOLUCIONES 2024'!$J82 -> -883
A83: Enviado | B83: 81 | C83: 45323 | D83: ACHAHUANCO CACERES OMAR GERMAIN | E83: 018200281E | F83: DICTAMEN DE PROYECTO DE TESIS | J83: =TODAY() -> 46206 | K83: ='RESOLUCIONES 2024'!$C83-'RESOLUCIONES 2024'!$J83 -> -883
A84: Enviado | B84: 82 | C84: 45323 | D84: ROMERO COPACONDORI FIORELA AYDE | E84: 019300166B | F84: DICTAMEN DE PROYECTO DE TESIS | J84: =TODAY() -> 46206 | K84: ='RESOLUCIONES 2024'!$C84-'RESOLUCIONES 2024'!$J84 -> -883
A85: Enviado | B85: 83 | C85: 45323 | D85: RODRIGUEZ GONZALES KELLY | E85: 022300044I | F85: DICTAMEN DE PROYECTO DE TESIS | J85: =TODAY() -> 46206 | K85: ='RESOLUCIONES 2024'!$C85-'RESOLUCIONES 2024'!$J85 -> -883
A86: Enviado | B86: 84 | C86: 45323 | D86: FUENTES BERNEDO FRIDA ESMERALDA | E86: 022300036F | F86: DICTAMEN DE PROYECTO DE TESIS | J86: =TODAY() -> 46206 | K86: ='RESOLUCIONES 2024'!$C86-'RESOLUCIONES 2024'!$J86 -> -883
...

Sheet RESOLUCIONES 2023
A1: LAZO HERRERA THONY ABEL | J1: CARGOS
A2: N° SOLICITUD | B2: RESOL. N° | C2: FECHA | D2: NOMBRES Y APELLIDOS | E2: CODIGO2 | F2: TIPO DE RESOLUCION | G2: Obaservaciones | H2: RESOLUCION 2 | I2: Columna1 | J2: HOY | K2: Excede 730 Dias | L2: CARGO 3 | M2: CARGO 4 | N2: CARGO 5 | O2: CARGO 6
A3: Enviado | B3: 1 | C3: 44958 | D3: GUEVARA CANDIA RAFAEL FERNANDO | E3: 016201378D | F3: NOMBRAMIENTO DE ASESOR | J3: =TODAY() -> 46206 | K3: ='RESOLUCIONES 2023'!$C3-'RESOLUCIONES 2023'!$J3 -> -1248
A4: Enviado | B4: 2 | C4: 44958 | D4: OLIVERA ARREDONDO ALEJANDRO URIEL | E4: 019300059A | F4: NOMBRAMIENTO DE ASESOR | J4: =TODAY() -> 46206 | K4: ='RESOLUCIONES 2023'!$C4-'RESOLUCIONES 2023'!$J4 -> -1248
A5: Enviado | B5: 3 | C5: 44958 | D5: LUQUE FLOREZ EDWARD | E5: 018300052H | F5: INSCRIPCION DE PROYECTO DE TESIS | J5: =TODAY() -> 46206 | K5: ='RESOLUCIONES 2023'!$C5-'RESOLUCIONES 2023'!$J5 -> -1248
A6: Enviado | B6: 4 | C6: 44958 | D6: LOAIZA MORALES MAROLI ERNESTINA | E6: 018100040F | F6: INSCRIPCION DE PROYECTO DE TESIS | J6: =TODAY() -> 46206 | K6: ='RESOLUCIONES 2023'!$C6-'RESOLUCIONES 2023'!$J6 -> -1248
A7: Enviado | B7: 5 | C7: 44958 | D7: CORBACHO CARPIO ISABEL | E7: 016102367D | F7: INSCRIPCION DE PROYECTO DE TESIS | J7: =TODAY() -> 46206 | K7: ='RESOLUCIONES 2023'!$C7-'RESOLUCIONES 2023'!$J7 -> -1248
A8: Enviado | B8: 6 | C8: 44958 | D8: AUCCA MARIN EDWIN NILTON | E8: 017300005K | F8: INSCRIPCION DE PROYECTO DE TESIS | J8: =TODAY() -> 46206 | K8: ='RESOLUCIONES 2023'!$C8-'RESOLUCIONES 2023'!$J8 -> -1248
A9: Enviado | B9: 7 | C9: 44958 | D9: FARFAN ESCOBEDO WERNER ADAIR | E9: 017300095J | F9: INSCRIPCION DE PROYECTO DE TESIS | J9: =TODAY() -> 46206 | K9: ='RESOLUCIONES 2023'!$C9-'RESOLUCIONES 2023'!$J9 -> -1248
A10: Enviado | B10: 8 | C10: 44958 | D10: ZAVALA CACERES ESTER MARIBEL | E10: 020300032B | F10: INSCRIPCION DE PROYECTO DE TESIS | J10: =TODAY() -> 46206 | K10: ='RESOLUCIONES 2023'!$C10-'RESOLUCIONES 2023'!$J10 -> -1248
A11: Enviado | B11: 9 | C11: 44958 | D11: CASAFRANCA VILLACORTA NILTON | E11: 013200962G | F11: DICTAMEN DE TESIS | G11: Peña Farfan no labora en la UAC cambio de dictaminante | J11: =TODAY() -> 46206 | K11: ='RESOLUCIONES 2023'!$C11-'RESOLUCIONES 2023'!$J11 -> -1248
A12: Enviado | B12: 10 | C12: 44958 | D12: CCOPA ALEGRE JENNEFER PAOLA | E12: 021100060A | F12: DICTAMEN DE TESIS | J12: =TODAY() -> 46206 | K12: ='RESOLUCIONES 2023'!$C12-'RESOLUCIONES 2023'!$J12 -> -1248
A13: Enviado | B13: 11 | C13: 44958 | D13: VALVERDE VIZCARRA VANESSA MONICA | E13: 015101307I | F13: DICTAMEN DE TESIS | J13: =TODAY() -> 46206 | K13: ='RESOLUCIONES 2023'!$C13-'RESOLUCIONES 2023'!$J13 -> -1248
A14: Enviado | B14: 12 | C14: 44958 | D14: OCROS GUEVARA BERTOLT FERNANDO | E14: 019200354A | F14: DICTAMEN DE TESIS | J14: =TODAY() -> 46206 | K14: ='RESOLUCIONES 2023'!$C14-'RESOLUCIONES 2023'!$J14 -> -1248
A15: Enviado | B15: 13 | C15: 44958 | D15: TRUJILLO TEJADA JUAN CARLOS | E15: 011270075A | F15: DICTAMEN DE TESIS | J15: =TODAY() -> 46206 | K15: ='RESOLUCIONES 2023'!$C15-'RESOLUCIONES 2023'!$J15 -> -1248
A16: Enviado | B16: 14 | C16: 44958 | D16: GUEVARA CANDIA RAFAEL FERNANDO | E16: 016201378D | F16: DICTAMEN DE PROYECTO DE TESIS | J16: =TODAY() -> 46206 | K16: ='RESOLUCIONES 2023'!$C16-'RESOLUCIONES 2023'!$J16 -> -1248
A17: Enviado | B17: 15 | C17: 44958 | D17: CHAVEZ CAJIGAS JHENSS MALKYN | E17: 016201375E | F17: DICTAMEN DE PROYECTO DE TESIS | J17: =TODAY() -> 46206 | K17: ='RESOLUCIONES 2023'!$C17-'RESOLUCIONES 2023'!$J17 -> -1248
A18: Enviado | B18: 16 | C18: 44958 | D18: SERNA SILVA MIRIAN ZULEMA | E18: 019100021K | F18: DICTAMEN DE PROYECTO DE TESIS | J18: =TODAY() -> 46206 | K18: ='RESOLUCIONES 2023'!$C18-'RESOLUCIONES 2023'!$J18 -> -1248
A19: Enviado | B19: 17 | C19: 44958 | D19: FARROÑAN FLORES GABRIEL | E19: 019100098C | F19: DICTAMEN DE PROYECTO DE TESIS | J19: =TODAY() -> 46206 | K19: ='RESOLUCIONES 2023'!$C19-'RESOLUCIONES 2023'!$J19 -> -1248
A20: Enviado | B20: 18 | C20: 44958 | D20: SAYRE GAMARRA JAYNA MIRELIA | E20: 019100114I | F20: DICTAMEN DE PROYECTO DE TESIS | J20: =TODAY() -> 46206 | K20: ='RESOLUCIONES 2023'!$C20-'RESOLUCIONES 2023'!$J20 -> -1248
A21: Enviado | B21: 19 | C21: 44958 | D21: ROMAN BUSTINZA ANGELICA | E21: 017300130J | F21: DICTAMEN DE PROYECTO DE TESIS | J21: =TODAY() -> 46206 | K21: ='RESOLUCIONES 2023'!$C21-'RESOLUCIONES 2023'!$J21 -> -1248
A22: Enviado | B22: 20 | C22: 44964 | D22: MELENDEZ NINA JUAN FRANCISCO | E22: 015101554F | F22: EXPEDIENTE APTO AL GRADO | J22: =TODAY() -> 46206 | K22: ='RESOLUCIONES 2023'!$C22-'RESOLUCIONES 2023'!$J22 -> -1242
A23: Enviado | B23: 21 | C23: 44964 | D23: RAMOS PACHECO BETSY SURI | E23: 018100072E | F23: ELEVAR AL VRAC | G23: Doctor en Medio Ambiente y Desarrollo Sostenible. | J23: =TODAY() -> 46206 | K23: ='RESOLUCIONES 2023'!$C23-'RESOLUCIONES 2023'!$J23 -> -1242
A24: Enviado | B24: 22 | C24: 44964 | D24: TOVAR NINA LILLIBETH | E24: 016102359A | F24: ELEVAR AL VRAC | G24: Maestro en Administración de Negocios. | J24: =TODAY() -> 46206 | K24: ='RESOLUCIONES 2023'!$C24-'RESOLUCIONES 2023'!$J24 -> -1242
A25: Enviado | B25: 23 | C25: 44964 | D25: CALDERÓN SEGURA JUAN CARLOS FIDEL | E25: 017200232E | F25: ELEVAR AL VRAC | G25: Maestro en Seguridad Industrial y Medio Ambiente | J25: =TODAY() -> 46206 | K25: ='RESOLUCIONES 2023'!$C25-'RESOLUCIONES 2023'!$J25 -> -1242
A26: Enviado | B26: 24 | C26: 44964 | D26: CASTRO CERECEDA RUTH | E26: 010200009K | F26: ELEVAR AL VRAC | G26: Maestro en Docencia Universitaria. | J26: =TODAY() -> 46206 | K26: ='RESOLUCIONES 2023'!$C26-'RESOLUCIONES 2023'!$J26 -> -1242
A27: Enviado | B27: 25 | C27: 44965 | D27: LOAYZA BORDA JOSE ALEJANDRO | E27: 018200036K | F27: FIJAR FECHA Y HORA | G27: Se envio observaciones | J27: =TODAY() -> 46206 | K27: ='RESOLUCIONES 2023'!$C27-'RESOLUCIONES 2023'!$J27 -> -1241
A28: Enviado | B28: 26 | C28: 44965 | D28: ZUNIGA ESPINOZA NICO IVAN | E28: 015101447E | F28: FIJAR FECHA Y HORA | G28: Se envio observaciones | J28: =TODAY() -> 46206 | K28: ='RESOLUCIONES 2023'!$C28-'RESOLUCIONES 2023'!$J28 -> -1241
A29: Enviado | B29: 27 | C29: 44965 | D29: BUSTAMANTE JAEN JULIO DANILO | E29: 016102062I | F29: FIJAR FECHA Y HORA | G29: Se envio observaciones | J29: =TODAY() -> 46206 | K29: ='RESOLUCIONES 2023'!$C29-'RESOLUCIONES 2023'!$J29 -> -1241
A30: Enviado | B30: 28 | C30: 44965 | D30: SANJINES PEÑA YASKARA | E30: 016102357I | F30: FIJAR FECHA Y HORA | G30: Se envio observaciones | J30: =TODAY() -> 46206 | K30: ='RESOLUCIONES 2023'!$C30-'RESOLUCIONES 2023'!$J30 -> -1241
A31: Enviado | B31: 29 | C31: 44965 | D31: PANDO DIAZ WALDO MANUEL | E31: 019200285J | F31: FIJAR FECHA Y HORA | G31: Se envio observaciones | J31: =TODAY() -> 46206 | K31: ='RESOLUCIONES 2023'!$C31-'RESOLUCIONES 2023'!$J31 -> -1241
A32: Enviado | B32: 30 | C32: 44965 | D32: ANAYA CAHUA LUIS CARLOS | E32: 014101510J | F32: FIJAR FECHA Y HORA | G32: Se envio observaciones | J32: =TODAY() -> 46206 | K32: ='RESOLUCIONES 2023'!$C32-'RESOLUCIONES 2023'!$J32 -> -1241
A33: Enviado | B33: 31 | C33: 44965 | D33: PEÑA CHAVEZ MANUEL SEYBERLING | E33: 018100071I | F33: FIJAR FECHA Y HORA | G33: Suspendido | J33: =TODAY() -> 46206 | K33: ='RESOLUCIONES 2023'!$C33-'RESOLUCIONES 2023'!$J33 -> -1241
A34: Enviado | B34: 32 | C34: 44965 | D34: CORZO PALOMO ERIKA ELEANA | E34: 018300036B | F34: FIJAR FECHA Y HORA | G34: Se envio observaciones | J34: =TODAY() -> 46206 | K34: ='RESOLUCIONES 2023'!$C34-'RESOLUCIONES 2023'!$J34 -> -1241
... A40: Enviado | B40: 38 | C40: 44967 | D40: CARDENAS FLORES ROCIO MARLENI | E40: 017200026F | F40: FIJAR FECHA Y HORA | G40: Se envio observaciones | J40: =TODAY() -> 46206 | K40: ='RESOLUCIONES 2023'!$C40-'RESOLUCIONES 2023'!$J40 -> -1239
A41: Enviado | B41: 39 | C41: 44967 | D41: TRIGOSO DELGADO JORGE OSCAR | E41: 018200301F | F41: CAMBIO DE TITULO DE PROYECTO | J41: =TODAY() -> 46206 | K41: ='RESOLUCIONES 2023'!$C41-'RESOLUCIONES 2023'!$J41 -> -1239
A42: Enviado | B42: 40 | C42: 44970 | D42: JALIXTO CUYO SOLEDAD | E42: 016102344D | F42: APTO AL GRADO | J42: =TODAY() -> 46206 | K42: ='RESOLUCIONES 2023'!$C42-'RESOLUCIONES 2023'!$J42 -> -1236
A43: Enviado | B43: 41 | C43: 44970 | D43: CHAVEZ YABAR JULIO CESAR | E43: 011270014B | F43: APTO AL GRADO | J43: =TODAY() -> 46206 | K43: ='RESOLUCIONES 2023'!$C43-'RESOLUCIONES 2023'!$J43 -> -1236
A44: Enviado | B44: 42 | C44: 44970 | D44: BALLON VALER YULIANA | E44: 011270005C | F44: APTO AL GRADO | J44: =TODAY() -> 46206 | K44: ='RESOLUCIONES 2023'!$C44-'RESOLUCIONES 2023'!$J44 -> -1236
A45: Enviado | B45: 43 | C45: 44970 | D45: ANAYA CENTENO GUSTAVO | E45: 019200241B | F45: APTO AL GRADO | J45: =TODAY() -> 46206 | K45: ='RESOLUCIONES 2023'!$C45-'RESOLUCIONES 2023'!$J45 -> -1236
...

Sheet RESOLUCIONES 2022
A1: RESOLUCIONES EMITIDAS 2022 | J1: CARGOS
A2: N° SOLICITUD | B2: RESOL. N° | C2: FECHA | D2: NOMBRES Y APELLIDOS | E2: CODIGO2 | F2: TIPO DE RESOLUCION | G2: Obaservaciones | H2: RESOLUCION 2 | I2: Columna1 | J2: HOY | K2: Excede 730 Dias | L2: CARGO 3 | M2: CARGO 4 | N2: CARGO 5 | O2: CARGO 6
A3: Enviado | B3: 1 | C3: 44572 | D3: BARRANTES OROS ZUNEI BRISHAELLY | E3: 016102383J | F3: DICTAMEN PROYECTO DE TESIS | J3: =TODAY() -> 46206 | K3: ='RESOLUCIONES 2022'!$C3-'RESOLUCIONES 2022'!$J3 -> -1634
A4: Enviado | B4: 2 | C4: 44572 | D4: LOAIZA LIVANO NOELY ESMERALDA | E4: 017300070G | F4: DICTAMEN PROYECTO DE TESIS | J4: =TODAY() -> 46206 | K4: ='RESOLUCIONES 2022'!$C4-'RESOLUCIONES 2022'!$J4 -> -1634
A5: Enviado | B5: 3 | C5: 44572 | D5: OLIVARES TORRE GRETEL ROXANA | E5: 019200033K | F5: DICTAMEN PROYECTO DE TESIS | J5: =TODAY() -> 46206 | K5: ='RESOLUCIONES 2022'!$C5-'RESOLUCIONES 2022'!$J5 -> -1634
A6: Enviado | B6: 4 | C6: 44572 | D6: AQUEPUCHO BELLOTA RUDYARD WILHELM | E6: 019100059H | F6: DICTAMEN PROYECTO DE TESIS | J6: =TODAY() -> 46206 | K6: ='RESOLUCIONES 2022'!$C6-'RESOLUCIONES 2022'!$J6 -> -1634
A7: Enviado | B7: 5 | C7: 44572 | D7: PORCEL HUILLCA IVAN | E7: 019200418J | F7: DICTAMEN PROYECTO DE TESIS | J7: =TODAY() -> 46206 | K7: ='RESOLUCIONES 2022'!$C7-'RESOLUCIONES 2022'!$J7 -> -1634
A8: Enviado | B8: 6 | C8: 44572 | D8: COAQUIRA CASTILLO ROGER JESUS | E8: 019300084F | F8: DICTAMEN PROYECTO DE TESIS | J8: =TODAY() -> 46206 | K8: ='RESOLUCIONES 2022'!$C8-'RESOLUCIONES 2022'!$J8 -> -1634
A9: Enviado | B9: 7 | C9: 44572 | D9: ACHAHUANCO ACHAHUI GORKI EDUARDO | E9: 014101487H | F9: DICTAMEN PROYECTO DE TESIS | J9: =TODAY() -> 46206 | K9: ='RESOLUCIONES 2022'!$C9-'RESOLUCIONES 2022'!$J9 -> -1634
A10: Enviado | B10: 8 | C10: 44572 | D10: GUTIERREZ TUPAYACHI VIRANSHELY MILAGROS | E10: 021100066J | F10: DICTAMEN PROYECTO DE TESIS | J10: =TODAY() -> 46206 | K10: ='RESOLUCIONES 2022'!$C10-'RESOLUCIONES 2022'!$J10 -> -1634
A11: Enviado | B11: 9 | C11: 44572 | D11: QUISPE ESPINOZA ROXANA | E11: 018200012D | F11: DICTAMEN PROYECTO DE TESIS | J11: =TODAY() -> 46206 | K11: ='RESOLUCIONES 2022'!$C11-'RESOLUCIONES 2022'!$J11 -> -1634
A12: Enviado | B12: 10 | C12: 44572 | D12: TACURI QUEJIA GUADALUPE | E12: 020200077D | F12: DICTAMEN PROYECTO DE TESIS | J12: =TODAY() -> 46206 | K12: ='RESOLUCIONES 2022'!$C12-'RESOLUCIONES 2022'!$J12 -> -1634
A13: Enviado | B13: 11 | C13: 44572 | D13: CHILLIHUANI CASA SANDRA | E13: 019300007A | F13: DICTAMEN PROYECTO DE TESIS | J13: =TODAY() -> 46206 | K13: ='RESOLUCIONES 2022'!$C13-'RESOLUCIONES 2022'!$J13 -> -1634
A14: Enviado | B14: 12 | C14: 44575 | D14: VERA MUÑOZ ESTEFANY LORENA | E14: 020300199D | F14: AUTORIZAR LA SUBSANACION | G14: RIVERA MUÑOZ JORGE LEONCIO | J14: =TODAY() -> 46206 | K14: ='RESOLUCIONES 2022'!$C14-'RESOLUCIONES 2022'!$J14 -> -1631
A15: Enviado | B15: 13 | C15: 44589 | D15: QUILCA JIMENEZ JUAN CARLOS | E15: 016201405A | F15: Cambio de Asesor del Proyecto de Tesis | G15: CHACALTANA PISCONTE JULIO GUILLERMO | J15: =TODAY() -> 46206 | K15: ='RESOLUCIONES 2022'!$C15-'RESOLUCIONES 2022'!$J15 -> -1617
A16: Enviado | B16: 14 | C16: 44589 | D16: AQUEPUCHO BELLOTA RUDYARD WILHELM | E16: 019100059H | F16: Cambio de Asesor del Proyecto de Tesis | G16: ESPEJO ABARCA KAROLA | J16: =TODAY() -> 46206 | K16: ='RESOLUCIONES 2022'!$C16-'RESOLUCIONES 2022'!$J16 -> -1617
A17: Enviado | B17: 15 | C17: 44589 | D17: ALVAREZ RIOS CRISTINA | E17: 019100058A | F17: Cambio de Asesor del Proyecto de Tesis | G17: DE LA TORRE DUEÑAS CLETO | J17: =TODAY() -> 46206 | K17: ='RESOLUCIONES 2022'!$C17-'RESOLUCIONES 2022'!$J17 -> -1617
A18: Enviado | B18: 16 | C18: 44592 | D18: GAMARRA SALAS JONATHAN | E18: 015101318K | F18: EXPEDIENTE APTO AL GRADO | J18: =TODAY() -> 46206 | K18: ='RESOLUCIONES 2022'!$C18-'RESOLUCIONES 2022'!$J18 -> -1614
A19: Enviado | B19: 17 | C19: 44592 | D19: MERINO YEPEZ ROBERT MILTON | E19: 015201383I | F19: EXPEDIENTE APTO AL GRADO | J19: =TODAY() -> 46206 | K19: ='RESOLUCIONES 2022'!$C19-'RESOLUCIONES 2022'!$J19 -> -1614
A20: Enviado | B20: 18 | C20: 44592 | D20: BERDEJO GUADALUPE SONIA | E20: 019200333D | F20: EXPEDIENTE APTO AL GRADO | J20: =TODAY() -> 46206 | K20: ='RESOLUCIONES 2022'!$C20-'RESOLUCIONES 2022'!$J20 -> -1614
A21: Enviado | B21: 19 | C21: 44592 | D21: TRIGOSO DELGADO JORGE OSCAR | E21: 018200301F | F21: EXPEDIENTE APTO AL GRADO | J21: =TODAY() -> 46206 | K21: ='RESOLUCIONES 2022'!$C21-'RESOLUCIONES 2022'!$J21 -> -1614
A22: Enviado | B22: 20 | C22: 44592 | D22: ALVAREZ LOPINTA CELIA | E22: 018300038E | F22: EXPEDIENTE APTO AL GRADO | J22: =TODAY() -> 46206 | K22: ='RESOLUCIONES 2022'!$C22-'RESOLUCIONES 2022'!$J22 -> -1614
B23: 21 | C23: 44592 | D23: VERA MUÑOZ ESTEFANY LORENA | E23: 020300199D | F23: RECONOCER NOTA SUBSANACION | G23: RIVERA MUÑOZ JORGE LEONCIO | J23: =TODAY() -> 46206 | K23: ='RESOLUCIONES 2022'!$C23-'RESOLUCIONES 2022'!$J23 -> -1614
B24: 22 | C24: 44592 | D24: TEJEIRA FLORES DANIEL | E24: 020300154K | F24: RECONOCER NOTA SUBSANACION | G24: MURILLO FLORES LUIS FERNANDO | J24: =TODAY() -> 46206 | K24: ='RESOLUCIONES 2022'!$C24-'RESOLUCIONES 2022'!$J24 -> -1614
B25: 23 | C25: 44592 | D25: SEQUEIROS MORALES JOSE LUIS | E25: 019300023G | F25: RECONOCER NOTA SUBSANACION | G25: MURILLO FLORES LUIS FERNANDO | J25: =TODAY() -> 46206 | K25: ='RESOLUCIONES 2022'!$C25-'RESOLUCIONES 2022'!$J25 -> -1614
B26: 24 | C26: 44592 | D26: SANCHEZ ACURIO RUTH MARTHA | E26: 020300152H | F26: RECONOCER NOTA SUBSANACION | G26: MURILLO FLORES LUIS FERNANDO | J26: =TODAY() -> 46206 | K26: ='RESOLUCIONES 2022'!$C26-'RESOLUCIONES 2022'!$J26 -> -1614
B27: 25 | C27: 44592 | D27: QUISPE CHIPA JANETH MILAGROS | E27: 020300150E | F27: RECONOCER NOTA SUBSANACION | G27: MURILLO FLORES LUIS FERNANDO | J27: =TODAY() -> 46206 | K27: ='RESOLUCIONES 2022'!$C27-'RESOLUCIONES 2022'!$J27 -> -1614
B28: 26 | C28: 44592 | D28: PUMA CCAÑIHUA PERCY | E28: 020300149G | F28: RECONOCER NOTA SUBSANACION | G28: MURILLO FLORES LUIS FERNANDO | J28: =TODAY() -> 46206 | K28: ='RESOLUCIONES 2022'!$C28-'RESOLUCIONES 2022'!$J28 -> -1614
B29: 27 | C29: 44592 | D29: PACCO CJURO ZORAIDA | E29: 019300019J | F29: RECONOCER NOTA SUBSANACION | G29: MURILLO FLORES LUIS FERNANDO | J29: =TODAY() -> 46206 | K29: ='RESOLUCIONES 2022'!$C29-'RESOLUCIONES 2022'!$J29 -> -1614
B30: 28 | C30: 44592 | D30: FLOREZ CORIMANYA ANGEL VITALIANO | E30: 020300139A | F30: RECONOCER NOTA SUBSANACION | G30: MURILLO FLORES LUIS FERNANDO | J30: =TODAY() -> 46206 | K30: ='RESOLUCIONES 2022'!$C30-'RESOLUCIONES 2022'!$J30 -> -1614
B31: 29 | C31: 44592 | D31: FLOREZ CORIMANYA ANGEL VITALIANO | E31: 020300139A | F31: RECONOCER NOTA SUBSANACION | G31: MURILLO FLORES LUIS FERNANDO | J31: =TODAY() -> 46206 | K31: ='RESOLUCIONES 2022'!$C31-'RESOLUCIONES 2022'!$J31 -> -1614
B32: 30 | C32: 44592 | D32: SANTA CRUZ QUISPE YONY | E32: 020300153D | F32: RECONOCER NOTA SUBSANACION | G32: MURILLO FLORES LUIS FERNANDO | J32: =TODAY() -> 46206 | K32: ='RESOLUCIONES 2022'!$C32-'RESOLUCIONES 2022'!$J32 -> -1614
B33: 31 | C33: 44592 | D33: BLANCO CUPARA EDERWALDO | E33: 020300129F | F33: RECONOCER NOTA SUBSANACION | G33: MURILLO FLORES LUIS FERNANDO | J33: =TODAY() -> 46206 | K33: ='RESOLUCIONES 2022'!$C33-'RESOLUCIONES 2022'!$J33 -> -1614
B34: 32 | C34: 44592 | D34: ALCCA QUINTE HENRY MICHAEL | E34: 020300127C | F34: RECONOCER NOTA SUBSANACION | G34: MURILLO FLORES LUIS FERNANDO | J34: =TODAY() -> 46206 | K34: ='RESOLUCIONES 2022'!$C34-'RESOLUCIONES 2022'!$J34 -> -1614
... B37: 35 | C37: 44592 | D37: CABRERA CASTILLA EDDY JONATAN | E37: 021300115D | F37: RECONOCER NOTA SUBSANACION | G37: HOLGUIN HERRERA DONNY ALEJANDRO | J37: =TODAY() -> 46206 | K37: ='RESOLUCIONES 2022'!$C37-'RESOLUCIONES 2022'!$J37 -> -1614
A38: Enviado | B38: 36 | C38: 44595 | D38: HUANCAHUIRE ALLENDE YORDAN JESÚS | E38: 018200259J | F38: EXPEDIENTE APTO AL GRADO | J38: =TODAY() -> 46206 | K38: ='RESOLUCIONES 2022'!$C38-'RESOLUCIONES 2022'!$J38 -> -1611
A39: Enviado | B39: 37 | C39: 44595 | D39: HUARANCCA VALDERRAMA ROSA AMALIA | E39: 013201123I | F39: EXPEDIENTE APTO AL GRADO | J39: =TODAY() -> 46206 | K39: ='RESOLUCIONES 2022'!$C39-'RESOLUCIONES 2022'!$J39 -> -1611
A40: Enviado | B40: 38 | C40: 44595 | D40: RIVAS LOAIZA CONNY | E40: 018300033C | F40: EXPEDIENTE APTO AL GRADO | J40: =TODAY() -> 46206 | K40: ='RESOLUCIONES 2022'!$C40-'RESOLUCIONES 2022'!$J40 -> -1611
A41: Enviado | B41: 39 | C41: 44595 | D41: ROJAS PARIONA CARMEN ROSA | E41: 013201095E | F41: EXPEDIENTE APTO AL GRADO | J41: =TODAY() -> 46206 | K41: ='RESOLUCIONES 2022'!$C41-'RESOLUCIONES 2022'!$J41 -> -1611
A42: Enviado | B42: 40 | C42: 44595 | D42: PUMA RIMACHI JHON RONALD | E42: 020300101D | F42: NOMBRAMIENTO DE ASESOR | G42: TRESIERRA PANTIGOZO ABEL | J42: =TODAY() -> 46206 | K42: ='RESOLUCIONES 2022'!$C42-'RESOLUCIONES 2022'!$J42 -> -1611
...

Sheet RESOLUCIONES 2021
A1: RESOLUCIONES EMITIDAS 2021 | J1: CARGOS
A2: N° SOLICITUD | B2: RESOL. N° | C2: FECHA | D2: NOMBRES Y APELLIDOS | E2: CODIGO2 | F2: TIPO DE RESOLUCION | G2: Obaservaciones | H2: RESOLUCION 2 | I2: Columna1 | J2: DICTAMEN 1 | K2: DICTAMEN 2 | L2: CARGO 3 | M2: CARGO 4 | N2: CARGO 5
A3: Enviado | B3: 1 | C3: 44200 | D3: APAZA CANAZA FELIPE | E3: 019300030C | F3: NOMBRAMIENTO ASESOR | G3: SHAILI JULIE CAVERO PACHECO
A4: Enviado | B4: 2 | C4: 44200 | D4: TELLO TACO BRYAN MANUEL​ | E4: 019300192C | F4: NOMBRAMIENTO ASESOR | G4: CARLOS ALBERTO PASTOR CARRASCO
A5: Enviado | B5: 3 | C5: 44200 | D5: CASTRO VEGA KARLA VERENISSE | E5: 017200265K | F5: NOMBRAMIENTO ASESOR | G5: FERNANDO PHILCO PRADO
A6: Enviado | B6: 4 | C6: 44200 | D6: FLORES MORALES NAY RUTH | E6: 019300181A | F6: NOMBRAMIENTO ASESOR | G6: CARLOS ALBERTO PASTOR CARRASCO,
A7: Enviado | B7: 5 | C7: 44200 | D7: MAGUIÑA APAZA ANNY ISABEL | E7: 018200066G | F7: INSCRIPCION DE PROYECTO
A8: Enviado | B8: 6 | C8: 44200 | D8: ANAYA CAHUA LUIS CARLOS | E8: 014101510J | F8: INSCRIPCION DE PROYECTO
A9: Enviado | B9: 7 | C9: 44200 | D9: BACA UMERES ISELA | E9: 008270004B | F9: INSCRIPCION DE PROYECTO
A10: Enviado | B10: 8 | C10: 44200 | D10: QUISPE RAMOS ESTELA | E10: 018200298E | F10: INSCRIPCION DE PROYECTO
A11: Enviado | B11: 9 | C11: 44200 | D11: FERNANDEZ LARA ALEX | E11: 017200169A | F11: INSCRIPCION DE PROYECTO
A12: Enviado | B12: 10 | C12: 44200 | D12: HUILLCAHUA SIERRA HILBERHT | E12: 019200343J | F12: DICTAMEN DE PROYECTO
A13: Enviado | B13: 11 | C13: 44200 | D13: ​ CHOQQUENAYRA CHOQUENEYRA ZENAIDA SOFIA | E13: 019300203E | F13: DICTAMEN DE PROYECTO
A14: Enviado | B14: 12 | C14: 44200 | D14: GARCIA CUIPA EDER | E14: 019100135F | F14: DICTAMEN DE PROYECTO | J14: Herminia Naveda De Aramburu
A15: Enviado | B15: 13 | C15: 44200 | D15: TRIGOSO DELGADO JORGE OSCAR | E15: 018200301F | F15: DICTAMEN DE PROYECTO
A16: Enviado | B16: 14 | C16: 44200 | D16: MAYHUIRE MONTOYA VICTOR ABRAHAM | E16: 019200153F | F16: DICTAMEN DE PROYECTO
A17: Enviado | B17: 15 | C17: 44200 | D17: GUTIERREZ ACUÑA YENI | E17: 018100060G | F17: CAMBIO DE TITULO DE LA TESIS
B18: 16 | C18: 44200 | D18: MOSQUEIRA VILLALBA TANIA | E18: 016102191C | F18: ELEVAR AL VRAC | G18: SEGURIDAD INDUSTRIAL Y MEDIO AMBIENTE
B19: 17 | C19: 44200 | D19: HIDALGO LEON MANUEL EDUARDO | E19: 014101473G | F19: ELEVAR AL VRAC | G19: DOCENCIA UNIVERSITARIA
B20: 18 | C20: 44200 | D20: RIVERO YNFANTAS FERNANDO | E20: 012200935K | F20: ELEVAR AL VRAC | G20: DOCTORADO EN DERECHO
B21: 19 | C21: 44200 | D21: HUAMAN FARFAN TAHIRI | E21: 43550804 | F21: ELEVAR AL VRAC | G21: MAESTRIA EN ESTOMATOLOGIA
B22: 20
A23: Enviado | B23: 21 | C23: 44238 | D23: CALDERON SEGURA JUAN CARLOS FIDEL | E23: 017200232E | F23: INSCRIPCION DE PROYECTO
A24: Enviado | B24: 22 | C24: 44238 | D24: PUMA HUANCO LIZBETH EVELYN | E24: 019300164J | F24: RECONOCER SUBSANACION | G24: WALTER HERNAN ARAUJO BERRÍO
A25: Enviado | B25: 23 | C25: 44238 | D25: WARTHON CALERO JARIB ANTENOR | E25: 017300111E | F25: AUTORIZAR SUBSANACION | G25: RIOS MAYORGA JULIO TRINIDAD | H25: falta reconocimiento
A26: Enviado | B26: 24 | C26: 44238 | D26: QUISPE CUSIHUAMAN MARIA ANGELICA | E26: 019300062B | F26: NOMBRAMIENTO ASESOR | G26: melendrez velasco elias
A27: Enviado | B27: 25 | C27: 44238 | D27: QUISPE DIAZ JEANETTE | E27: 019300063I | F27: NOMBRAMIENTO ASESOR | G27: melendrez velasco elias
A28: Enviado | B28: 26 | C28: 44238 | D28: NAVARRO GONZALES RAISA PAMELA | E28: 016102193F | F28: NOMBRAMIENTO ASESOR | G28: JHIMI WALTER PIETRI ABARCA
A29: Enviado | B29: 27 | C29: 44238 | D29: MARTINEZ ACURIO ANDREI | E29: 019300054J | F29: NOMBRAMIENTO ASESOR | G29: melendrez velasco elias
